Workbook

Sheet Data
A1: 1 | B1: 10 | C1: apple | G1: x | H1: y | I1: z | K1: -100
A2: 2 | B2: 20 | C2: banana | G2: 1 | H2: 2 | I2: 3 | K2: 60
A3: 3 | B3: 30 | C3: cherry | K3: 60
A4: 4 | B4: 40 | C4: apple
A5: 5 | B5: 50 | C5: banana
A6: 6 | B6: 60 | C6: cherry
A7: 7 | B7: 70 | C7: apple
A8: 8 | B8: 80 | C8: banana
A9: 9 | B9: 90 | C9: cherry
A10: 10 | B10: 100 | C10: apple

Sheet Cases
A1: =SUM(Data!A1:A10)
A2: =SUMIF(Data!C1:C10,"apple",Data!B1:B10)
A3: =SUMIFS(Data!B1:B10,Data!C1:C10,"banana",Data!A1:A10,">2")
A4: =SUMPRODUCT(Data!A1:A10,Data!B1:B10)
A5: =AVERAGE(Data!A1:A10)
A6: =AVERAGEIF(Data!C1:C10,"cherry",Data!B1:B10)
A7: =AVERAGEIFS(Data!B1:B10,Data!C1:C10,"apple",Data!A1:A10,"<=7")
A8: =COUNT(Data!A1:A10,Data!C1:C3)
A9: =COUNTA(Data!A1:C10)
A10: =COUNTBLANK(Data!E1:E10)
A11: =COUNTIF(Data!C1:C10,"apple")
A12: =COUNTIFS(Data!C1:C10,"banana",Data!A1:A10,">=5")
A13: =MAX(Data!A1:A10)
A14: =_xlfn.MAXIFS(Data!B1:B10,Data!C1:C10,"banana")
A15: =MIN(Data!B1:B10)
A16: =_xlfn.MINIFS(Data!B1:B10,Data!C1:C10,"cherry")
A17: =ROUND(2.567,2)
A18: =ROUNDUP(2.561,2)
A19: =ROUNDDOWN(2.569,2)
A20: =INT(-2.5)
A21: =MOD(-7,3)
A22: =ABS(-3.5)
A23: =CEILING(2.1,0.5)
A24: =FLOOR(2.9,0.5)
A25: =POWER(2,10)
A26: =SQRT(144)
A27: =PRODUCT(Data!A1:A5)
A28: =RAND()
A29: =RANDBETWEEN(5,10)
A30: =SIGN(-9)
A31: =TRUNC(-8.9)
A32: =LN(EXP(1))
A33: =LOG(8,2)
A34: =LOG10(1000)
A35: =EXP(0)
A36: =SUBTOTAL(9,Data!A1:A10)
A37: =_xlfn.AGGREGATE(9,6,Data!A1:A10)
A38: =MEDIAN(Data!B1:B10)
A39: =MODE(1,2,2,3,3,3)
A40: =LARGE(Data!B1:B10,2)
...
